[2025-09-28 09:46:09,434] INFO in __init__: Logging initialized.
[2025-09-28 09:46:20,177] INFO in __init__: Logging initialized.
[2025-09-28 09:46:25,600] INFO in __init__: Logging initialized.
[2025-09-28 09:46:34,529] INFO in __init__: Logging initialized.
[2025-09-28 09:47:01,654] INFO in __init__: Logging initialized.
[2025-09-28 09:53:11,586] INFO in __init__: Logging initialized.
[2025-09-28 10:00:08,438] INFO in __init__: Logging initialized.
[2025-09-28 10:03:01,753] INFO in __init__: Logging initialized.
[2025-09-28 10:12:39,692] ERROR in app: Exception on /support/my [GET]
Traceback (most recent call last):
  File "C:\Users\buule\Desktop\TaskDesk\dfy\venv\lib\site-packages\flask\app.py", line 1511, in wsgi_app
    response = self.full_dispatch_request()
  File "C:\Users\buule\Desktop\TaskDesk\dfy\venv\lib\site-packages\flask\app.py", line 919, in full_dispatch_request
    rv = self.handle_user_exception(e)
  File "C:\Users\buule\Desktop\TaskDesk\dfy\venv\lib\site-packages\flask\app.py", line 917, in full_dispatch_request
    rv = self.dispatch_request()
  File "C:\Users\buule\Desktop\TaskDesk\dfy\venv\lib\site-packages\flask\app.py", line 902, in dispatch_request
    return self.ensure_sync(self.view_functions[rule.endpoint])(**view_args)  # type: ignore[no-any-return]
  File "C:\Users\buule\Desktop\TaskDesk\dfy\venv\lib\site-packages\flask_login\utils.py", line 290, in decorated_view
    return current_app.ensure_sync(func)(*args, **kwargs)
  File "C:\Users\buule\Desktop\TaskDesk\dfy\app\blueprints\main\routes.py", line 215, in support_my
  File "C:\Users\buule\Desktop\TaskDesk\dfy\venv\lib\site-packages\flask\templating.py", line 149, in render_template
    template = app.jinja_env.get_or_select_template(template_name_or_list)
  File "C:\Users\buule\Desktop\TaskDesk\dfy\venv\lib\site-packages\jinja2\environment.py", line 1087, in get_or_select_template
    return self.get_template(template_name_or_list, parent, globals)
  File "C:\Users\buule\Desktop\TaskDesk\dfy\venv\lib\site-packages\jinja2\environment.py", line 1016, in get_template
    return self._load_template(name, globals)
  File "C:\Users\buule\Desktop\TaskDesk\dfy\venv\lib\site-packages\jinja2\environment.py", line 975, in _load_template
    template = self.loader.load(self, name, self.make_globals(globals))
  File "C:\Users\buule\Desktop\TaskDesk\dfy\venv\lib\site-packages\jinja2\loaders.py", line 126, in load
    source, filename, uptodate = self.get_source(environment, name)
  File "C:\Users\buule\Desktop\TaskDesk\dfy\venv\lib\site-packages\flask\templating.py", line 65, in get_source
    return self._get_source_fast(environment, template)
  File "C:\Users\buule\Desktop\TaskDesk\dfy\venv\lib\site-packages\flask\templating.py", line 99, in _get_source_fast
    raise TemplateNotFound(template)
jinja2.exceptions.TemplateNotFound: support_my.html
[2025-09-28 10:14:25,956] INFO in __init__: Logging initialized.
[2025-09-28 10:21:56,052] INFO in __init__: Logging initialized.
[2025-09-28 10:25:19,973] INFO in __init__: Logging initialized.
[2025-09-28 10:30:42,550] INFO in __init__: Logging initialized.
[2025-09-28 10:50:38,922] INFO in __init__: Logging initialized.
[2025-09-28 10:50:48,645] INFO in __init__: Logging initialized.
[2025-09-28 10:51:13,717] INFO in __init__: Logging initialized.
[2025-09-28 10:51:24,027] INFO in __init__: Logging initialized.
[2025-09-28 10:51:31,366] INFO in __init__: Logging initialized.
[2025-09-28 10:55:52,880] INFO in __init__: Logging initialized.
[2025-09-28 10:55:58,169] ERROR in app: Exception on /terms [GET]
Traceback (most recent call last):
  File "C:\Users\buule\Desktop\TaskDesk\dfy\venv\lib\site-packages\flask\app.py", line 1511, in wsgi_app
    response = self.full_dispatch_request()
  File "C:\Users\buule\Desktop\TaskDesk\dfy\venv\lib\site-packages\flask\app.py", line 919, in full_dispatch_request
    rv = self.handle_user_exception(e)
  File "C:\Users\buule\Desktop\TaskDesk\dfy\venv\lib\site-packages\flask\app.py", line 917, in full_dispatch_request
    rv = self.dispatch_request()
  File "C:\Users\buule\Desktop\TaskDesk\dfy\venv\lib\site-packages\flask\app.py", line 902, in dispatch_request
    return self.ensure_sync(self.view_functions[rule.endpoint])(**view_args)  # type: ignore[no-any-return]
  File "C:\Users\buule\Desktop\TaskDesk\dfy\app\blueprints\main\routes.py", line 20, in terms
    return render_template("static/terms.html")
  File "C:\Users\buule\Desktop\TaskDesk\dfy\venv\lib\site-packages\flask\templating.py", line 150, in render_template
    return _render(app, template, context)
  File "C:\Users\buule\Desktop\TaskDesk\dfy\venv\lib\site-packages\flask\templating.py", line 131, in _render
    rv = template.render(context)
  File "C:\Users\buule\Desktop\TaskDesk\dfy\venv\lib\site-packages\jinja2\environment.py", line 1295, in render
    self.environment.handle_exception()
  File "C:\Users\buule\Desktop\TaskDesk\dfy\venv\lib\site-packages\jinja2\environment.py", line 942, in handle_exception
    raise rewrite_traceback_stack(source=source)
  File "C:\Users\buule\Desktop\TaskDesk\dfy\app\templates\static\terms.html", line 1, in top-level template code
    {% extends 'base.html' %} {% set title = 'Terms of Service â€” TaskDesk' %} {% block extra_css %}
  File "C:\Users\buule\Desktop\TaskDesk\dfy\app\templates\base.html", line 195, in top-level template code
    <form method="post" action="{{ url_for('main.subscribe_post') }}" class="newsletter d-flex flex-wrap gap-2">
  File "C:\Users\buule\Desktop\TaskDesk\dfy\venv\lib\site-packages\flask\app.py", line 1121, in url_for
    return self.handle_url_build_error(error, endpoint, values)
  File "C:\Users\buule\Desktop\TaskDesk\dfy\venv\lib\site-packages\flask\app.py", line 1110, in url_for
    rv = url_adapter.build(  # type: ignore[union-attr]
  File "C:\Users\buule\Desktop\TaskDesk\dfy\venv\lib\site-packages\werkzeug\routing\map.py", line 924, in build
    raise BuildError(endpoint, values, method, self)
werkzeug.routing.exceptions.BuildError: Could not build url for endpoint 'main.subscribe_post'. Did you mean 'main.support_thread_post' instead?
[2025-09-28 10:55:59,130] ERROR in app: Exception on /favicon.ico [GET]
Traceback (most recent call last):
  File "C:\Users\buule\Desktop\TaskDesk\dfy\venv\lib\site-packages\flask\app.py", line 917, in full_dispatch_request
    rv = self.dispatch_request()
  File "C:\Users\buule\Desktop\TaskDesk\dfy\venv\lib\site-packages\flask\app.py", line 891, in dispatch_request
    self.raise_routing_exception(req)
  File "C:\Users\buule\Desktop\TaskDesk\dfy\venv\lib\site-packages\flask\app.py", line 500, in raise_routing_exception
    raise request.routing_exception  # type: ignore[misc]
  File "C:\Users\buule\Desktop\TaskDesk\dfy\venv\lib\site-packages\flask\ctx.py", line 362, in match_request
    result = self.url_adapter.match(return_rule=True)  # type: ignore
  File "C:\Users\buule\Desktop\TaskDesk\dfy\venv\lib\site-packages\werkzeug\routing\map.py", line 629, in match
    raise NotFound() from None
werkzeug.exceptions.NotFound: 404 Not Found: The requested URL was not found on the server. If you entered the URL manually please check your spelling and try again.

During handling of the above exception, another exception occurred:

Traceback (most recent call last):
  File "C:\Users\buule\Desktop\TaskDesk\dfy\venv\lib\site-packages\flask\app.py", line 1511, in wsgi_app
    response = self.full_dispatch_request()
  File "C:\Users\buule\Desktop\TaskDesk\dfy\venv\lib\site-packages\flask\app.py", line 919, in full_dispatch_request
    rv = self.handle_user_exception(e)
  File "C:\Users\buule\Desktop\TaskDesk\dfy\venv\lib\site-packages\flask\app.py", line 802, in handle_user_exception
    return self.handle_http_exception(e)
  File "C:\Users\buule\Desktop\TaskDesk\dfy\venv\lib\site-packages\flask\app.py", line 777, in handle_http_exception
    return self.ensure_sync(handler)(e)  # type: ignore[no-any-return]
  File "C:\Users\buule\Desktop\TaskDesk\dfy\app\__init__.py", line 149, in not_found_error
    return render_template("errors/404.html"), 404
  File "C:\Users\buule\Desktop\TaskDesk\dfy\venv\lib\site-packages\flask\templating.py", line 150, in render_template
    return _render(app, template, context)
  File "C:\Users\buule\Desktop\TaskDesk\dfy\venv\lib\site-packages\flask\templating.py", line 131, in _render
    rv = template.render(context)
  File "C:\Users\buule\Desktop\TaskDesk\dfy\venv\lib\site-packages\jinja2\environment.py", line 1295, in render
    self.environment.handle_exception()
  File "C:\Users\buule\Desktop\TaskDesk\dfy\venv\lib\site-packages\jinja2\environment.py", line 942, in handle_exception
    raise rewrite_traceback_stack(source=source)
  File "C:\Users\buule\Desktop\TaskDesk\dfy\app\templates\errors\404.html", line 1, in top-level template code
    {% extends 'base.html' %} {% block content %}
  File "C:\Users\buule\Desktop\TaskDesk\dfy\app\templates\base.html", line 195, in top-level template code
    <form method="post" action="{{ url_for('main.subscribe_post') }}" class="newsletter d-flex flex-wrap gap-2">
  File "C:\Users\buule\Desktop\TaskDesk\dfy\venv\lib\site-packages\flask\app.py", line 1121, in url_for
    return self.handle_url_build_error(error, endpoint, values)
  File "C:\Users\buule\Desktop\TaskDesk\dfy\venv\lib\site-packages\flask\app.py", line 1110, in url_for
    rv = url_adapter.build(  # type: ignore[union-attr]
  File "C:\Users\buule\Desktop\TaskDesk\dfy\venv\lib\site-packages\werkzeug\routing\map.py", line 924, in build
    raise BuildError(endpoint, values, method, self)
werkzeug.routing.exceptions.BuildError: Could not build url for endpoint 'main.subscribe_post'. Did you mean 'main.support_thread_post' instead?
[2025-09-28 11:03:22,397] INFO in __init__: Logging initialized.
[2025-09-28 11:06:15,022] INFO in __init__: Logging initialized.
[2025-09-28 11:06:43,077] INFO in __init__: Logging initialized.
[2025-09-28 11:48:33,813] INFO in __init__: Logging initialized.
[2025-09-28 11:56:00,072] INFO in __init__: Logging initialized.
[2025-09-28 11:56:37,470] ERROR in app: Exception on /admin/inbox [GET]
Traceback (most recent call last):
  File "C:\Users\buule\Desktop\TaskDesk\dfy\venv\lib\site-packages\flask\app.py", line 1511, in wsgi_app
    response = self.full_dispatch_request()
  File "C:\Users\buule\Desktop\TaskDesk\dfy\venv\lib\site-packages\flask\app.py", line 919, in full_dispatch_request
    rv = self.handle_user_exception(e)
  File "C:\Users\buule\Desktop\TaskDesk\dfy\venv\lib\site-packages\flask\app.py", line 917, in full_dispatch_request
    rv = self.dispatch_request()
  File "C:\Users\buule\Desktop\TaskDesk\dfy\venv\lib\site-packages\flask\app.py", line 902, in dispatch_request
    return self.ensure_sync(self.view_functions[rule.endpoint])(**view_args)  # type: ignore[no-any-return]
  File "C:\Users\buule\Desktop\TaskDesk\dfy\venv\lib\site-packages\flask_login\utils.py", line 290, in decorated_view
    return current_app.ensure_sync(func)(*args, **kwargs)
  File "C:\Users\buule\Desktop\TaskDesk\dfy\app\security.py", line 16, in wrapper
    return fn(*args, **kwargs)
  File "C:\Users\buule\Desktop\TaskDesk\dfy\app\blueprints\admin\inbox.py", line 84, in inbox
    return render_template(
  File "C:\Users\buule\Desktop\TaskDesk\dfy\venv\lib\site-packages\flask\templating.py", line 150, in render_template
    return _render(app, template, context)
  File "C:\Users\buule\Desktop\TaskDesk\dfy\venv\lib\site-packages\flask\templating.py", line 131, in _render
    rv = template.render(context)
  File "C:\Users\buule\Desktop\TaskDesk\dfy\venv\lib\site-packages\jinja2\environment.py", line 1295, in render
    self.environment.handle_exception()
  File "C:\Users\buule\Desktop\TaskDesk\dfy\venv\lib\site-packages\jinja2\environment.py", line 942, in handle_exception
    raise rewrite_traceback_stack(source=source)
  File "C:\Users\buule\Desktop\TaskDesk\dfy\app\templates\admin\inbox.html", line 1, in top-level template code
    {% extends 'base.html' %} {% from 'macros.html' import progress_cell, task_status_progress %} {% block content %} {# Admin Inbox + Dashboard tools Context: - tasks: List[TaskRequest] - freelancers: optional List[User] - page, pages: optional ints - counts:
  File "C:\Users\buule\Desktop\TaskDesk\dfy\app\templates\base.html", line 149, in top-level template code
    {% endif %} {% endwith %} {% block content %}{% endblock %}
  File "C:\Users\buule\Desktop\TaskDesk\dfy\app\templates\admin\inbox.html", line 25, in block 'content'
    <a href="{{ url_for('admin_marketing.subscribers_list') }}" class="btn btn-sm btn-outline-primary">ðŸ“° Subscriptions</a>
  File "C:\Users\buule\Desktop\TaskDesk\dfy\venv\lib\site-packages\flask\app.py", line 1121, in url_for
    return self.handle_url_build_error(error, endpoint, values)
  File "C:\Users\buule\Desktop\TaskDesk\dfy\venv\lib\site-packages\flask\app.py", line 1110, in url_for
    rv = url_adapter.build(  # type: ignore[union-attr]
  File "C:\Users\buule\Desktop\TaskDesk\dfy\venv\lib\site-packages\werkzeug\routing\map.py", line 924, in build
    raise BuildError(endpoint, values, method, self)
werkzeug.routing.exceptions.BuildError: Could not build url for endpoint 'admin_marketing.subscribers_list'. Did you mean 'admin.subscribers_list' instead?
[2025-09-28 11:57:53,120] ERROR in app: Exception on /admin/inbox [GET]
Traceback (most recent call last):
  File "C:\Users\buule\Desktop\TaskDesk\dfy\venv\lib\site-packages\flask\app.py", line 1511, in wsgi_app
    response = self.full_dispatch_request()
  File "C:\Users\buule\Desktop\TaskDesk\dfy\venv\lib\site-packages\flask\app.py", line 919, in full_dispatch_request
    rv = self.handle_user_exception(e)
  File "C:\Users\buule\Desktop\TaskDesk\dfy\venv\lib\site-packages\flask\app.py", line 917, in full_dispatch_request
    rv = self.dispatch_request()
  File "C:\Users\buule\Desktop\TaskDesk\dfy\venv\lib\site-packages\flask\app.py", line 902, in dispatch_request
    return self.ensure_sync(self.view_functions[rule.endpoint])(**view_args)  # type: ignore[no-any-return]
  File "C:\Users\buule\Desktop\TaskDesk\dfy\venv\lib\site-packages\flask_login\utils.py", line 290, in decorated_view
    return current_app.ensure_sync(func)(*args, **kwargs)
  File "C:\Users\buule\Desktop\TaskDesk\dfy\app\security.py", line 16, in wrapper
    return fn(*args, **kwargs)
  File "C:\Users\buule\Desktop\TaskDesk\dfy\app\blueprints\admin\inbox.py", line 84, in inbox
    return render_template(
  File "C:\Users\buule\Desktop\TaskDesk\dfy\venv\lib\site-packages\flask\templating.py", line 150, in render_template
    return _render(app, template, context)
  File "C:\Users\buule\Desktop\TaskDesk\dfy\venv\lib\site-packages\flask\templating.py", line 131, in _render
    rv = template.render(context)
  File "C:\Users\buule\Desktop\TaskDesk\dfy\venv\lib\site-packages\jinja2\environment.py", line 1295, in render
    self.environment.handle_exception()
  File "C:\Users\buule\Desktop\TaskDesk\dfy\venv\lib\site-packages\jinja2\environment.py", line 942, in handle_exception
    raise rewrite_traceback_stack(source=source)
  File "C:\Users\buule\Desktop\TaskDesk\dfy\app\templates\admin\inbox.html", line 1, in top-level template code
    {% extends 'base.html' %} {% from 'macros.html' import progress_cell, task_status_progress %} {% block content %} {# Admin Inbox + Dashboard tools Context: - tasks: List[TaskRequest] - freelancers: optional List[User] - page, pages: optional ints - counts:
  File "C:\Users\buule\Desktop\TaskDesk\dfy\app\templates\base.html", line 149, in top-level template code
    {% endif %} {% endwith %} {% block content %}{% endblock %}
  File "C:\Users\buule\Desktop\TaskDesk\dfy\app\templates\admin\inbox.html", line 25, in block 'content'
    <a href="{{ url_for('admin.subscribers_list') }}" class="btn btn-sm btn-outline-primary">ðŸ“° Subscriptions</a>
  File "C:\Users\buule\Desktop\TaskDesk\dfy\venv\lib\site-packages\flask\app.py", line 1121, in url_for
    return self.handle_url_build_error(error, endpoint, values)
  File "C:\Users\buule\Desktop\TaskDesk\dfy\venv\lib\site-packages\flask\app.py", line 1110, in url_for
    rv = url_adapter.build(  # type: ignore[union-attr]
  File "C:\Users\buule\Desktop\TaskDesk\dfy\venv\lib\site-packages\werkzeug\routing\map.py", line 924, in build
    raise BuildError(endpoint, values, method, self)
werkzeug.routing.exceptions.BuildError: Could not build url for endpoint 'admin_marketing.subscribers_list'. Did you mean 'admin.subscribers_list' instead?
[2025-09-28 11:58:04,174] INFO in __init__: Logging initialized.
[2025-09-28 11:58:16,353] ERROR in app: Exception on /admin/subscribers [GET]
Traceback (most recent call last):
  File "C:\Users\buule\Desktop\TaskDesk\dfy\venv\lib\site-packages\flask\app.py", line 1511, in wsgi_app
    response = self.full_dispatch_request()
  File "C:\Users\buule\Desktop\TaskDesk\dfy\venv\lib\site-packages\flask\app.py", line 919, in full_dispatch_request
    rv = self.handle_user_exception(e)
  File "C:\Users\buule\Desktop\TaskDesk\dfy\venv\lib\site-packages\flask\app.py", line 917, in full_dispatch_request
    rv = self.dispatch_request()
  File "C:\Users\buule\Desktop\TaskDesk\dfy\venv\lib\site-packages\flask\app.py", line 902, in dispatch_request
    return self.ensure_sync(self.view_functions[rule.endpoint])(**view_args)  # type: ignore[no-any-return]
  File "C:\Users\buule\Desktop\TaskDesk\dfy\app\blueprints\admin\marketing.py", line 40, in subscribers_list
    return render_template("admin/subscribers_list.html", subs=subs)
  File "C:\Users\buule\Desktop\TaskDesk\dfy\venv\lib\site-packages\flask\templating.py", line 150, in render_template
    return _render(app, template, context)
  File "C:\Users\buule\Desktop\TaskDesk\dfy\venv\lib\site-packages\flask\templating.py", line 131, in _render
    rv = template.render(context)
  File "C:\Users\buule\Desktop\TaskDesk\dfy\venv\lib\site-packages\jinja2\environment.py", line 1295, in render
    self.environment.handle_exception()
  File "C:\Users\buule\Desktop\TaskDesk\dfy\venv\lib\site-packages\jinja2\environment.py", line 942, in handle_exception
    raise rewrite_traceback_stack(source=source)
  File "C:\Users\buule\Desktop\TaskDesk\dfy\app\templates\admin\subscribers_list.html", line 1, in top-level template code
    {% extends 'base.html' %} {% block content %}
  File "C:\Users\buule\Desktop\TaskDesk\dfy\app\templates\base.html", line 149, in top-level template code
    {% endif %} {% endwith %} {% block content %}{% endblock %}
  File "C:\Users\buule\Desktop\TaskDesk\dfy\app\templates\admin\subscribers_list.html", line 6, in block 'content'
    <a class="btn btn-outline-secondary" href="{{ url_for('admin_marketing.subscribers_export_csv') }}">Export CSV</a>
  File "C:\Users\buule\Desktop\TaskDesk\dfy\venv\lib\site-packages\flask\app.py", line 1121, in url_for
    return self.handle_url_build_error(error, endpoint, values)
  File "C:\Users\buule\Desktop\TaskDesk\dfy\venv\lib\site-packages\flask\app.py", line 1110, in url_for
    rv = url_adapter.build(  # type: ignore[union-attr]
  File "C:\Users\buule\Desktop\TaskDesk\dfy\venv\lib\site-packages\werkzeug\routing\map.py", line 924, in build
    raise BuildError(endpoint, values, method, self)
werkzeug.routing.exceptions.BuildError: Could not build url for endpoint 'admin_marketing.subscribers_export_csv'. Did you mean 'admin.subscribers_export_csv' instead?
[2025-09-28 12:01:12,089] INFO in __init__: Logging initialized.
[2025-09-28 12:01:27,707] ERROR in app: Exception on /admin/subscribers [GET]
Traceback (most recent call last):
  File "C:\Users\buule\Desktop\TaskDesk\dfy\venv\lib\site-packages\flask\app.py", line 1511, in wsgi_app
    response = self.full_dispatch_request()
  File "C:\Users\buule\Desktop\TaskDesk\dfy\venv\lib\site-packages\flask\app.py", line 919, in full_dispatch_request
    rv = self.handle_user_exception(e)
  File "C:\Users\buule\Desktop\TaskDesk\dfy\venv\lib\site-packages\flask\app.py", line 917, in full_dispatch_request
    rv = self.dispatch_request()
  File "C:\Users\buule\Desktop\TaskDesk\dfy\venv\lib\site-packages\flask\app.py", line 902, in dispatch_request
    return self.ensure_sync(self.view_functions[rule.endpoint])(**view_args)  # type: ignore[no-any-return]
  File "C:\Users\buule\Desktop\TaskDesk\dfy\app\blueprints\admin\marketing.py", line 40, in subscribers_list
    return render_template("admin/subscribers_list.html", subs=subs)
  File "C:\Users\buule\Desktop\TaskDesk\dfy\venv\lib\site-packages\flask\templating.py", line 150, in render_template
    return _render(app, template, context)
  File "C:\Users\buule\Desktop\TaskDesk\dfy\venv\lib\site-packages\flask\templating.py", line 131, in _render
    rv = template.render(context)
  File "C:\Users\buule\Desktop\TaskDesk\dfy\venv\lib\site-packages\jinja2\environment.py", line 1295, in render
    self.environment.handle_exception()
  File "C:\Users\buule\Desktop\TaskDesk\dfy\venv\lib\site-packages\jinja2\environment.py", line 942, in handle_exception
    raise rewrite_traceback_stack(source=source)
  File "C:\Users\buule\Desktop\TaskDesk\dfy\app\templates\admin\subscribers_list.html", line 1, in top-level template code
    {% extends 'base.html' %} {% block content %}
  File "C:\Users\buule\Desktop\TaskDesk\dfy\app\templates\base.html", line 149, in top-level template code
    {% endif %} {% endwith %} {% block content %}{% endblock %}
  File "C:\Users\buule\Desktop\TaskDesk\dfy\app\templates\admin\subscribers_list.html", line 7, in block 'content'
    <a class="btn btn-primary" href="{{ url_for('admin_marketing.campaigns_new') }}">New Campaign</a>
  File "C:\Users\buule\Desktop\TaskDesk\dfy\venv\lib\site-packages\flask\app.py", line 1121, in url_for
    return self.handle_url_build_error(error, endpoint, values)
  File "C:\Users\buule\Desktop\TaskDesk\dfy\venv\lib\site-packages\flask\app.py", line 1110, in url_for
    rv = url_adapter.build(  # type: ignore[union-attr]
  File "C:\Users\buule\Desktop\TaskDesk\dfy\venv\lib\site-packages\werkzeug\routing\map.py", line 924, in build
    raise BuildError(endpoint, values, method, self)
werkzeug.routing.exceptions.BuildError: Could not build url for endpoint 'admin_marketing.campaigns_new'. Did you mean 'admin.campaigns_new' instead?
[2025-09-28 12:05:11,688] INFO in __init__: Logging initialized.
[2025-09-28 12:29:22,036] INFO in __init__: Logging initialized.
[2025-09-28 12:49:53,455] INFO in __init__: Logging initialized.
[2025-09-28 13:21:41,402] INFO in __init__: Logging initialized.
[2025-09-28 13:21:44,548] ERROR in app: Exception on / [GET]
Traceback (most recent call last):
  File "C:\Users\buule\Desktop\TaskDesk\dfy\venv\lib\site-packages\flask\app.py", line 1511, in wsgi_app
    response = self.full_dispatch_request()
  File "C:\Users\buule\Desktop\TaskDesk\dfy\venv\lib\site-packages\flask\app.py", line 919, in full_dispatch_request
    rv = self.handle_user_exception(e)
  File "C:\Users\buule\Desktop\TaskDesk\dfy\venv\lib\site-packages\flask\app.py", line 917, in full_dispatch_request
    rv = self.dispatch_request()
  File "C:\Users\buule\Desktop\TaskDesk\dfy\venv\lib\site-packages\flask\app.py", line 902, in dispatch_request
    return self.ensure_sync(self.view_functions[rule.endpoint])(**view_args)  # type: ignore[no-any-return]
  File "C:\Users\buule\Desktop\TaskDesk\dfy\app\__init__.py", line 162, in index
    return render_template("home.html")
  File "C:\Users\buule\Desktop\TaskDesk\dfy\venv\lib\site-packages\flask\templating.py", line 150, in render_template
    return _render(app, template, context)
  File "C:\Users\buule\Desktop\TaskDesk\dfy\venv\lib\site-packages\flask\templating.py", line 131, in _render
    rv = template.render(context)
  File "C:\Users\buule\Desktop\TaskDesk\dfy\venv\lib\site-packages\jinja2\environment.py", line 1295, in render
    self.environment.handle_exception()
  File "C:\Users\buule\Desktop\TaskDesk\dfy\venv\lib\site-packages\jinja2\environment.py", line 942, in handle_exception
    raise rewrite_traceback_stack(source=source)
  File "C:\Users\buule\Desktop\TaskDesk\dfy\app\templates\home.html", line 1, in top-level template code
    {% extends 'base.html' %} {% block content %} {# Home / Landing page for TaskDesk Images expected at /static/img/: hero.jpg, feature-1.jpg, feature-2.jpg, feature-3.jpg, how-1.jpg, how-2.jpg, how-3.jpg, logos/*.svg (company-1.svg ...), testimonial-*.jpg
  File "C:\Users\buule\Desktop\TaskDesk\dfy\app\templates\base.html", line 2, in top-level template code
    <html lang="{{ get_locale() or 'en' }}" data-bs-theme="light">
  File "C:\Users\buule\Desktop\TaskDesk\dfy\venv\lib\site-packages\jinja2\utils.py", line 92, in from_obj
    if hasattr(obj, "jinja_pass_arg"):
jinja2.exceptions.UndefinedError: 'get_locale' is undefined
[2025-09-28 13:21:44,977] ERROR in app: Exception on /favicon.ico [GET]
Traceback (most recent call last):
  File "C:\Users\buule\Desktop\TaskDesk\dfy\venv\lib\site-packages\flask\app.py", line 917, in full_dispatch_request
    rv = self.dispatch_request()
  File "C:\Users\buule\Desktop\TaskDesk\dfy\venv\lib\site-packages\flask\app.py", line 891, in dispatch_request
    self.raise_routing_exception(req)
  File "C:\Users\buule\Desktop\TaskDesk\dfy\venv\lib\site-packages\flask\app.py", line 500, in raise_routing_exception
    raise request.routing_exception  # type: ignore[misc]
  File "C:\Users\buule\Desktop\TaskDesk\dfy\venv\lib\site-packages\flask\ctx.py", line 362, in match_request
    result = self.url_adapter.match(return_rule=True)  # type: ignore
  File "C:\Users\buule\Desktop\TaskDesk\dfy\venv\lib\site-packages\werkzeug\routing\map.py", line 629, in match
    raise NotFound() from None
werkzeug.exceptions.NotFound: 404 Not Found: The requested URL was not found on the server. If you entered the URL manually please check your spelling and try again.

During handling of the above exception, another exception occurred:

Traceback (most recent call last):
  File "C:\Users\buule\Desktop\TaskDesk\dfy\venv\lib\site-packages\flask\app.py", line 1511, in wsgi_app
    response = self.full_dispatch_request()
  File "C:\Users\buule\Desktop\TaskDesk\dfy\venv\lib\site-packages\flask\app.py", line 919, in full_dispatch_request
    rv = self.handle_user_exception(e)
  File "C:\Users\buule\Desktop\TaskDesk\dfy\venv\lib\site-packages\flask\app.py", line 802, in handle_user_exception
    return self.handle_http_exception(e)
  File "C:\Users\buule\Desktop\TaskDesk\dfy\venv\lib\site-packages\flask\app.py", line 777, in handle_http_exception
    return self.ensure_sync(handler)(e)  # type: ignore[no-any-return]
  File "C:\Users\buule\Desktop\TaskDesk\dfy\app\__init__.py", line 166, in not_found_error
    return render_template("errors/404.html"), 404
  File "C:\Users\buule\Desktop\TaskDesk\dfy\venv\lib\site-packages\flask\templating.py", line 150, in render_template
    return _render(app, template, context)
  File "C:\Users\buule\Desktop\TaskDesk\dfy\venv\lib\site-packages\flask\templating.py", line 131, in _render
    rv = template.render(context)
  File "C:\Users\buule\Desktop\TaskDesk\dfy\venv\lib\site-packages\jinja2\environment.py", line 1295, in render
    self.environment.handle_exception()
  File "C:\Users\buule\Desktop\TaskDesk\dfy\venv\lib\site-packages\jinja2\environment.py", line 942, in handle_exception
    raise rewrite_traceback_stack(source=source)
  File "C:\Users\buule\Desktop\TaskDesk\dfy\app\templates\errors\404.html", line 1, in top-level template code
    {% extends 'base.html' %} {% block content %}
  File "C:\Users\buule\Desktop\TaskDesk\dfy\app\templates\base.html", line 2, in top-level template code
    <html lang="{{ get_locale() or 'en' }}" data-bs-theme="light">
  File "C:\Users\buule\Desktop\TaskDesk\dfy\venv\lib\site-packages\jinja2\utils.py", line 92, in from_obj
    if hasattr(obj, "jinja_pass_arg"):
jinja2.exceptions.UndefinedError: 'get_locale' is undefined
[2025-09-28 13:27:33,464] INFO in __init__: Logging initialized.
[2025-09-28 13:27:47,619] INFO in routes: [i18n] lang set -> de
[2025-09-28 13:28:54,414] INFO in routes: [i18n] lang set -> fr
[2025-09-28 13:44:46,410] INFO in __init__: Logging initialized.
[2025-09-28 13:59:49,434] INFO in __init__: Logging initialized.
[2025-09-28 14:00:09,648] INFO in __init__: Logging initialized.
[2025-09-28 14:06:50,766] INFO in __init__: Logging initialized.
[2025-09-28 14:06:58,756] INFO in __init__: Logging initialized.
[2025-09-28 14:07:14,653] INFO in __init__: Logging initialized.
[2025-09-28 14:11:32,307] INFO in __init__: Logging initialized.
[2025-09-28 14:16:02,521] INFO in __init__: Logging initialized.
[2025-09-28 14:18:43,786] INFO in __init__: Logging initialized.
[2025-09-28 14:27:04,312] INFO in __init__: Logging initialized.
[2025-09-28 14:44:49,626] INFO in __init__: Logging initialized.
[2025-09-28 14:44:59,469] INFO in __init__: Logging initialized.
[2025-09-28 14:58:59,302] INFO in __init__: Logging initialized.
[2025-09-28 15:13:56,530] INFO in __init__: Logging initialized.
[2025-09-28 15:38:32,176] INFO in __init__: Logging initialized.
[2025-09-28 15:43:01,876] INFO in __init__: Logging initialized.
[2025-09-28 15:45:31,660] INFO in __init__: Logging initialized.
[2025-09-28 15:56:06,959] INFO in __init__: Logging initialized.
[2025-09-28 15:56:14,080] ERROR in app: Exception on / [GET]
Traceback (most recent call last):
  File "C:\Users\buule\Desktop\TaskDesk\dfy\venv\lib\site-packages\flask\app.py", line 1511, in wsgi_app
    response = self.full_dispatch_request()
  File "C:\Users\buule\Desktop\TaskDesk\dfy\venv\lib\site-packages\flask\app.py", line 919, in full_dispatch_request
    rv = self.handle_user_exception(e)
  File "C:\Users\buule\Desktop\TaskDesk\dfy\venv\lib\site-packages\flask\app.py", line 917, in full_dispatch_request
    rv = self.dispatch_request()
  File "C:\Users\buule\Desktop\TaskDesk\dfy\venv\lib\site-packages\flask\app.py", line 902, in dispatch_request
    return self.ensure_sync(self.view_functions[rule.endpoint])(**view_args)  # type: ignore[no-any-return]
  File "C:\Users\buule\Desktop\TaskDesk\dfy\app\__init__.py", line 205, in index
    return render_template("home.html")
  File "C:\Users\buule\Desktop\TaskDesk\dfy\venv\lib\site-packages\flask\templating.py", line 150, in render_template
    return _render(app, template, context)
  File "C:\Users\buule\Desktop\TaskDesk\dfy\venv\lib\site-packages\flask\templating.py", line 131, in _render
    rv = template.render(context)
  File "C:\Users\buule\Desktop\TaskDesk\dfy\venv\lib\site-packages\jinja2\environment.py", line 1295, in render
    self.environment.handle_exception()
  File "C:\Users\buule\Desktop\TaskDesk\dfy\venv\lib\site-packages\jinja2\environment.py", line 942, in handle_exception
    raise rewrite_traceback_stack(source=source)
  File "C:\Users\buule\Desktop\TaskDesk\dfy\app\templates\home.html", line 1, in top-level template code
    {% extends 'base.html' %} {% block content %} {# Home / Landing page for TaskDesk Images expected at /static/img/: hero.jpg, feature-1.jpg, feature-2.jpg, feature-3.jpg, how-1.jpg, how-2.jpg, how-3.jpg, logos/*.svg (company-1.svg ...), testimonial-*.jpg
  File "C:\Users\buule\Desktop\TaskDesk\dfy\app\templates\base.html", line 169, in top-level template code
    <a class="navbar-brand d-flex align-items-center" href="{{ url_for('main.index') }}">
  File "C:\Users\buule\Desktop\TaskDesk\dfy\venv\lib\site-packages\flask\app.py", line 1121, in url_for
    return self.handle_url_build_error(error, endpoint, values)
  File "C:\Users\buule\Desktop\TaskDesk\dfy\venv\lib\site-packages\flask\app.py", line 1110, in url_for
    rv = url_adapter.build(  # type: ignore[union-attr]
  File "C:\Users\buule\Desktop\TaskDesk\dfy\venv\lib\site-packages\werkzeug\routing\map.py", line 924, in build
    raise BuildError(endpoint, values, method, self)
werkzeug.routing.exceptions.BuildError: Could not build url for endpoint 'main.index'. Did you mean 'admin.inbox' instead?
[2025-09-28 15:56:14,360] ERROR in app: Exception on /favicon.ico [GET]
Traceback (most recent call last):
  File "C:\Users\buule\Desktop\TaskDesk\dfy\venv\lib\site-packages\flask\app.py", line 917, in full_dispatch_request
    rv = self.dispatch_request()
  File "C:\Users\buule\Desktop\TaskDesk\dfy\venv\lib\site-packages\flask\app.py", line 891, in dispatch_request
    self.raise_routing_exception(req)
  File "C:\Users\buule\Desktop\TaskDesk\dfy\venv\lib\site-packages\flask\app.py", line 500, in raise_routing_exception
    raise request.routing_exception  # type: ignore[misc]
  File "C:\Users\buule\Desktop\TaskDesk\dfy\venv\lib\site-packages\flask\ctx.py", line 362, in match_request
    result = self.url_adapter.match(return_rule=True)  # type: ignore
  File "C:\Users\buule\Desktop\TaskDesk\dfy\venv\lib\site-packages\werkzeug\routing\map.py", line 629, in match
    raise NotFound() from None
werkzeug.exceptions.NotFound: 404 Not Found: The requested URL was not found on the server. If you entered the URL manually please check your spelling and try again.

During handling of the above exception, another exception occurred:

Traceback (most recent call last):
  File "C:\Users\buule\Desktop\TaskDesk\dfy\venv\lib\site-packages\flask\app.py", line 1511, in wsgi_app
    response = self.full_dispatch_request()
  File "C:\Users\buule\Desktop\TaskDesk\dfy\venv\lib\site-packages\flask\app.py", line 919, in full_dispatch_request
    rv = self.handle_user_exception(e)
  File "C:\Users\buule\Desktop\TaskDesk\dfy\venv\lib\site-packages\flask\app.py", line 802, in handle_user_exception
    return self.handle_http_exception(e)
  File "C:\Users\buule\Desktop\TaskDesk\dfy\venv\lib\site-packages\flask\app.py", line 777, in handle_http_exception
    return self.ensure_sync(handler)(e)  # type: ignore[no-any-return]
  File "C:\Users\buule\Desktop\TaskDesk\dfy\app\__init__.py", line 209, in not_found_error
    return render_template("errors/404.html"), 404
  File "C:\Users\buule\Desktop\TaskDesk\dfy\venv\lib\site-packages\flask\templating.py", line 150, in render_template
    return _render(app, template, context)
  File "C:\Users\buule\Desktop\TaskDesk\dfy\venv\lib\site-packages\flask\templating.py", line 131, in _render
    rv = template.render(context)
  File "C:\Users\buule\Desktop\TaskDesk\dfy\venv\lib\site-packages\jinja2\environment.py", line 1295, in render
    self.environment.handle_exception()
  File "C:\Users\buule\Desktop\TaskDesk\dfy\venv\lib\site-packages\jinja2\environment.py", line 942, in handle_exception
    raise rewrite_traceback_stack(source=source)
  File "C:\Users\buule\Desktop\TaskDesk\dfy\app\templates\errors\404.html", line 1, in top-level template code
    {% extends 'base.html' %} {% block content %}
  File "C:\Users\buule\Desktop\TaskDesk\dfy\app\templates\base.html", line 169, in top-level template code
    <a class="navbar-brand d-flex align-items-center" href="{{ url_for('main.index') }}">
  File "C:\Users\buule\Desktop\TaskDesk\dfy\venv\lib\site-packages\flask\app.py", line 1121, in url_for
    return self.handle_url_build_error(error, endpoint, values)
  File "C:\Users\buule\Desktop\TaskDesk\dfy\venv\lib\site-packages\flask\app.py", line 1110, in url_for
    rv = url_adapter.build(  # type: ignore[union-attr]
  File "C:\Users\buule\Desktop\TaskDesk\dfy\venv\lib\site-packages\werkzeug\routing\map.py", line 924, in build
    raise BuildError(endpoint, values, method, self)
werkzeug.routing.exceptions.BuildError: Could not build url for endpoint 'main.index'. Did you mean 'admin.inbox' instead?
[2025-09-28 15:57:59,027] INFO in __init__: Logging initialized.
[2025-09-28 15:58:53,798] INFO in __init__: Logging initialized.
[2025-09-28 16:02:44,026] INFO in __init__: Logging initialized.
[2025-09-28 16:04:23,519] INFO in __init__: Logging initialized.
[2025-09-28 16:05:31,509] INFO in __init__: Logging initialized.
[2025-09-28 16:07:32,313] INFO in __init__: Logging initialized.
[2025-09-28 16:10:05,142] INFO in __init__: Logging initialized.
[2025-09-28 16:10:09,037] ERROR in app: Exception on / [GET]
Traceback (most recent call last):
  File "C:\Users\buule\Desktop\TaskDesk\dfy\venv\lib\site-packages\flask\app.py", line 1511, in wsgi_app
    response = self.full_dispatch_request()
  File "C:\Users\buule\Desktop\TaskDesk\dfy\venv\lib\site-packages\flask\app.py", line 919, in full_dispatch_request
    rv = self.handle_user_exception(e)
  File "C:\Users\buule\Desktop\TaskDesk\dfy\venv\lib\site-packages\flask\app.py", line 917, in full_dispatch_request
    rv = self.dispatch_request()
  File "C:\Users\buule\Desktop\TaskDesk\dfy\venv\lib\site-packages\flask\app.py", line 902, in dispatch_request
    return self.ensure_sync(self.view_functions[rule.endpoint])(**view_args)  # type: ignore[no-any-return]
  File "C:\Users\buule\Desktop\TaskDesk\dfy\app\__init__.py", line 205, in index
    return render_template("home.html")
  File "C:\Users\buule\Desktop\TaskDesk\dfy\venv\lib\site-packages\flask\templating.py", line 150, in render_template
    return _render(app, template, context)
  File "C:\Users\buule\Desktop\TaskDesk\dfy\venv\lib\site-packages\flask\templating.py", line 131, in _render
    rv = template.render(context)
  File "C:\Users\buule\Desktop\TaskDesk\dfy\venv\lib\site-packages\jinja2\environment.py", line 1295, in render
    self.environment.handle_exception()
  File "C:\Users\buule\Desktop\TaskDesk\dfy\venv\lib\site-packages\jinja2\environment.py", line 942, in handle_exception
    raise rewrite_traceback_stack(source=source)
  File "C:\Users\buule\Desktop\TaskDesk\dfy\app\templates\home.html", line 1, in top-level template code
    {% extends 'base.html' %} {% block content %} {# Home / Landing page for TaskDesk Images expected at /static/img/: hero.jpg, feature-1.jpg, feature-2.jpg, feature-3.jpg, how-1.jpg, how-2.jpg, how-3.jpg, logos/*.svg (company-1.svg ...), testimonial-*.jpg
  File "C:\Users\buule\Desktop\TaskDesk\dfy\app\templates\base.html", line 195, in top-level template code
    <a class="navbar-brand d-flex align-items-center" href="{{ url_for('main.index') }}">
  File "C:\Users\buule\Desktop\TaskDesk\dfy\venv\lib\site-packages\flask\app.py", line 1121, in url_for
    return self.handle_url_build_error(error, endpoint, values)
  File "C:\Users\buule\Desktop\TaskDesk\dfy\venv\lib\site-packages\flask\app.py", line 1110, in url_for
    rv = url_adapter.build(  # type: ignore[union-attr]
  File "C:\Users\buule\Desktop\TaskDesk\dfy\venv\lib\site-packages\werkzeug\routing\map.py", line 924, in build
    raise BuildError(endpoint, values, method, self)
werkzeug.routing.exceptions.BuildError: Could not build url for endpoint 'main.index'. Did you mean 'admin.inbox' instead?
[2025-09-28 16:10:09,171] ERROR in app: Exception on /favicon.ico [GET]
Traceback (most recent call last):
  File "C:\Users\buule\Desktop\TaskDesk\dfy\venv\lib\site-packages\flask\app.py", line 917, in full_dispatch_request
    rv = self.dispatch_request()
  File "C:\Users\buule\Desktop\TaskDesk\dfy\venv\lib\site-packages\flask\app.py", line 891, in dispatch_request
    self.raise_routing_exception(req)
  File "C:\Users\buule\Desktop\TaskDesk\dfy\venv\lib\site-packages\flask\app.py", line 500, in raise_routing_exception
    raise request.routing_exception  # type: ignore[misc]
  File "C:\Users\buule\Desktop\TaskDesk\dfy\venv\lib\site-packages\flask\ctx.py", line 362, in match_request
    result = self.url_adapter.match(return_rule=True)  # type: ignore
  File "C:\Users\buule\Desktop\TaskDesk\dfy\venv\lib\site-packages\werkzeug\routing\map.py", line 629, in match
    raise NotFound() from None
werkzeug.exceptions.NotFound: 404 Not Found: The requested URL was not found on the server. If you entered the URL manually please check your spelling and try again.

During handling of the above exception, another exception occurred:

Traceback (most recent call last):
  File "C:\Users\buule\Desktop\TaskDesk\dfy\venv\lib\site-packages\flask\app.py", line 1511, in wsgi_app
    response = self.full_dispatch_request()
  File "C:\Users\buule\Desktop\TaskDesk\dfy\venv\lib\site-packages\flask\app.py", line 919, in full_dispatch_request
    rv = self.handle_user_exception(e)
  File "C:\Users\buule\Desktop\TaskDesk\dfy\venv\lib\site-packages\flask\app.py", line 802, in handle_user_exception
    return self.handle_http_exception(e)
  File "C:\Users\buule\Desktop\TaskDesk\dfy\venv\lib\site-packages\flask\app.py", line 777, in handle_http_exception
    return self.ensure_sync(handler)(e)  # type: ignore[no-any-return]
  File "C:\Users\buule\Desktop\TaskDesk\dfy\app\__init__.py", line 209, in not_found_error
    return render_template("errors/404.html"), 404
  File "C:\Users\buule\Desktop\TaskDesk\dfy\venv\lib\site-packages\flask\templating.py", line 150, in render_template
    return _render(app, template, context)
  File "C:\Users\buule\Desktop\TaskDesk\dfy\venv\lib\site-packages\flask\templating.py", line 131, in _render
    rv = template.render(context)
  File "C:\Users\buule\Desktop\TaskDesk\dfy\venv\lib\site-packages\jinja2\environment.py", line 1295, in render
    self.environment.handle_exception()
  File "C:\Users\buule\Desktop\TaskDesk\dfy\venv\lib\site-packages\jinja2\environment.py", line 942, in handle_exception
    raise rewrite_traceback_stack(source=source)
  File "C:\Users\buule\Desktop\TaskDesk\dfy\app\templates\errors\404.html", line 1, in top-level template code
    {% extends 'base.html' %} {% block content %}
  File "C:\Users\buule\Desktop\TaskDesk\dfy\app\templates\base.html", line 195, in top-level template code
    <a class="navbar-brand d-flex align-items-center" href="{{ url_for('main.index') }}">
  File "C:\Users\buule\Desktop\TaskDesk\dfy\venv\lib\site-packages\flask\app.py", line 1121, in url_for
    return self.handle_url_build_error(error, endpoint, values)
  File "C:\Users\buule\Desktop\TaskDesk\dfy\venv\lib\site-packages\flask\app.py", line 1110, in url_for
    rv = url_adapter.build(  # type: ignore[union-attr]
  File "C:\Users\buule\Desktop\TaskDesk\dfy\venv\lib\site-packages\werkzeug\routing\map.py", line 924, in build
    raise BuildError(endpoint, values, method, self)
werkzeug.routing.exceptions.BuildError: Could not build url for endpoint 'main.index'. Did you mean 'admin.inbox' instead?
[2025-09-28 16:10:33,947] INFO in __init__: Logging initialized.
[2025-09-28 16:11:58,705] INFO in __init__: Logging initialized.
[2025-09-28 16:12:39,580] INFO in __init__: Logging initialized.
[2025-09-28 16:38:03,403] INFO in __init__: Logging initialized.
[2025-09-28 16:51:37,618] INFO in __init__: Logging initialized.
[2025-09-28 16:51:40,080] ERROR in app: Exception on / [GET]
Traceback (most recent call last):
  File "C:\Users\buule\Desktop\TaskDesk\dfy\venv\lib\site-packages\flask\app.py", line 1511, in wsgi_app
    response = self.full_dispatch_request()
  File "C:\Users\buule\Desktop\TaskDesk\dfy\venv\lib\site-packages\flask\app.py", line 919, in full_dispatch_request
    rv = self.handle_user_exception(e)
  File "C:\Users\buule\Desktop\TaskDesk\dfy\venv\lib\site-packages\flask\app.py", line 917, in full_dispatch_request
    rv = self.dispatch_request()
  File "C:\Users\buule\Desktop\TaskDesk\dfy\venv\lib\site-packages\flask\app.py", line 902, in dispatch_request
    return self.ensure_sync(self.view_functions[rule.endpoint])(**view_args)  # type: ignore[no-any-return]
  File "C:\Users\buule\Desktop\TaskDesk\dfy\app\__init__.py", line 205, in index
    return render_template("home.html")
  File "C:\Users\buule\Desktop\TaskDesk\dfy\venv\lib\site-packages\flask\templating.py", line 150, in render_template
    return _render(app, template, context)
  File "C:\Users\buule\Desktop\TaskDesk\dfy\venv\lib\site-packages\flask\templating.py", line 131, in _render
    rv = template.render(context)
  File "C:\Users\buule\Desktop\TaskDesk\dfy\venv\lib\site-packages\jinja2\environment.py", line 1295, in render
    self.environment.handle_exception()
  File "C:\Users\buule\Desktop\TaskDesk\dfy\venv\lib\site-packages\jinja2\environment.py", line 942, in handle_exception
    raise rewrite_traceback_stack(source=source)
  File "C:\Users\buule\Desktop\TaskDesk\dfy\app\templates\home.html", line 1, in top-level template code
    {% extends 'base.html' %} {% block content %} {# Home / Landing page for TaskDesk Images expected at /static/img/: hero.jpg, feature-1.jpg, feature-2.jpg, feature-3.jpg, how-1.jpg, how-2.jpg, how-3.jpg, logos/*.svg (company-1.svg ...), testimonial-*.jpg
  File "C:\Users\buule\Desktop\TaskDesk\dfy\app\templates\base.html", line 184, in top-level template code
    <a class="navbar-brand d-flex align-items-center" href="{{ url_for('main.index') }}">
  File "C:\Users\buule\Desktop\TaskDesk\dfy\venv\lib\site-packages\flask\app.py", line 1121, in url_for
    return self.handle_url_build_error(error, endpoint, values)
  File "C:\Users\buule\Desktop\TaskDesk\dfy\venv\lib\site-packages\flask\app.py", line 1110, in url_for
    rv = url_adapter.build(  # type: ignore[union-attr]
  File "C:\Users\buule\Desktop\TaskDesk\dfy\venv\lib\site-packages\werkzeug\routing\map.py", line 924, in build
    raise BuildError(endpoint, values, method, self)
werkzeug.routing.exceptions.BuildError: Could not build url for endpoint 'main.index'. Did you mean 'admin.inbox' instead?
[2025-09-28 16:51:40,171] ERROR in app: Exception on /favicon.ico [GET]
Traceback (most recent call last):
  File "C:\Users\buule\Desktop\TaskDesk\dfy\venv\lib\site-packages\flask\app.py", line 917, in full_dispatch_request
    rv = self.dispatch_request()
  File "C:\Users\buule\Desktop\TaskDesk\dfy\venv\lib\site-packages\flask\app.py", line 891, in dispatch_request
    self.raise_routing_exception(req)
  File "C:\Users\buule\Desktop\TaskDesk\dfy\venv\lib\site-packages\flask\app.py", line 500, in raise_routing_exception
    raise request.routing_exception  # type: ignore[misc]
  File "C:\Users\buule\Desktop\TaskDesk\dfy\venv\lib\site-packages\flask\ctx.py", line 362, in match_request
    result = self.url_adapter.match(return_rule=True)  # type: ignore
  File "C:\Users\buule\Desktop\TaskDesk\dfy\venv\lib\site-packages\werkzeug\routing\map.py", line 629, in match
    raise NotFound() from None
werkzeug.exceptions.NotFound: 404 Not Found: The requested URL was not found on the server. If you entered the URL manually please check your spelling and try again.

During handling of the above exception, another exception occurred:

Traceback (most recent call last):
  File "C:\Users\buule\Desktop\TaskDesk\dfy\venv\lib\site-packages\flask\app.py", line 1511, in wsgi_app
    response = self.full_dispatch_request()
  File "C:\Users\buule\Desktop\TaskDesk\dfy\venv\lib\site-packages\flask\app.py", line 919, in full_dispatch_request
    rv = self.handle_user_exception(e)
  File "C:\Users\buule\Desktop\TaskDesk\dfy\venv\lib\site-packages\flask\app.py", line 802, in handle_user_exception
    return self.handle_http_exception(e)
  File "C:\Users\buule\Desktop\TaskDesk\dfy\venv\lib\site-packages\flask\app.py", line 777, in handle_http_exception
    return self.ensure_sync(handler)(e)  # type: ignore[no-any-return]
  File "C:\Users\buule\Desktop\TaskDesk\dfy\app\__init__.py", line 209, in not_found_error
    return render_template("errors/404.html"), 404
  File "C:\Users\buule\Desktop\TaskDesk\dfy\venv\lib\site-packages\flask\templating.py", line 150, in render_template
    return _render(app, template, context)
  File "C:\Users\buule\Desktop\TaskDesk\dfy\venv\lib\site-packages\flask\templating.py", line 131, in _render
    rv = template.render(context)
  File "C:\Users\buule\Desktop\TaskDesk\dfy\venv\lib\site-packages\jinja2\environment.py", line 1295, in render
    self.environment.handle_exception()
  File "C:\Users\buule\Desktop\TaskDesk\dfy\venv\lib\site-packages\jinja2\environment.py", line 942, in handle_exception
    raise rewrite_traceback_stack(source=source)
  File "C:\Users\buule\Desktop\TaskDesk\dfy\app\templates\errors\404.html", line 1, in top-level template code
    {% extends 'base.html' %} {% block content %}
  File "C:\Users\buule\Desktop\TaskDesk\dfy\app\templates\base.html", line 184, in top-level template code
    <a class="navbar-brand d-flex align-items-center" href="{{ url_for('main.index') }}">
  File "C:\Users\buule\Desktop\TaskDesk\dfy\venv\lib\site-packages\flask\app.py", line 1121, in url_for
    return self.handle_url_build_error(error, endpoint, values)
  File "C:\Users\buule\Desktop\TaskDesk\dfy\venv\lib\site-packages\flask\app.py", line 1110, in url_for
    rv = url_adapter.build(  # type: ignore[union-attr]
  File "C:\Users\buule\Desktop\TaskDesk\dfy\venv\lib\site-packages\werkzeug\routing\map.py", line 924, in build
    raise BuildError(endpoint, values, method, self)
werkzeug.routing.exceptions.BuildError: Could not build url for endpoint 'main.index'. Did you mean 'admin.inbox' instead?
[2025-09-28 16:52:49,258] INFO in __init__: Logging initialized.
[2025-09-28 16:56:02,333] INFO in __init__: Logging initialized.
[2025-09-28 16:56:22,334] ERROR in app: Exception on / [GET]
Traceback (most recent call last):
  File "C:\Users\buule\Desktop\TaskDesk\dfy\venv\lib\site-packages\flask\app.py", line 1511, in wsgi_app
    response = self.full_dispatch_request()
  File "C:\Users\buule\Desktop\TaskDesk\dfy\venv\lib\site-packages\flask\app.py", line 919, in full_dispatch_request
    rv = self.handle_user_exception(e)
  File "C:\Users\buule\Desktop\TaskDesk\dfy\venv\lib\site-packages\flask\app.py", line 917, in full_dispatch_request
    rv = self.dispatch_request()
  File "C:\Users\buule\Desktop\TaskDesk\dfy\venv\lib\site-packages\flask\app.py", line 902, in dispatch_request
    return self.ensure_sync(self.view_functions[rule.endpoint])(**view_args)  # type: ignore[no-any-return]
  File "C:\Users\buule\Desktop\TaskDesk\dfy\app\__init__.py", line 205, in index
    return render_template("home.html")
  File "C:\Users\buule\Desktop\TaskDesk\dfy\venv\lib\site-packages\flask\templating.py", line 150, in render_template
    return _render(app, template, context)
  File "C:\Users\buule\Desktop\TaskDesk\dfy\venv\lib\site-packages\flask\templating.py", line 131, in _render
    rv = template.render(context)
  File "C:\Users\buule\Desktop\TaskDesk\dfy\venv\lib\site-packages\jinja2\environment.py", line 1295, in render
    self.environment.handle_exception()
  File "C:\Users\buule\Desktop\TaskDesk\dfy\venv\lib\site-packages\jinja2\environment.py", line 942, in handle_exception
    raise rewrite_traceback_stack(source=source)
  File "C:\Users\buule\Desktop\TaskDesk\dfy\app\templates\home.html", line 1, in top-level template code
    {% extends 'base.html' %} {% block content %} {# Home / Landing page for TaskDesk Images expected at /static/img/: hero.jpg, feature-1.jpg, feature-2.jpg, feature-3.jpg, how-1.jpg, how-2.jpg, how-3.jpg, logos/*.svg (company-1.svg ...), testimonial-*.jpg
  File "C:\Users\buule\Desktop\TaskDesk\dfy\app\templates\base.html", line 184, in top-level template code
    <a class="navbar-brand d-flex align-items-center" href="{{ url_for('main.index') }}">
  File "C:\Users\buule\Desktop\TaskDesk\dfy\venv\lib\site-packages\flask\app.py", line 1121, in url_for
    return self.handle_url_build_error(error, endpoint, values)
  File "C:\Users\buule\Desktop\TaskDesk\dfy\venv\lib\site-packages\flask\app.py", line 1110, in url_for
    rv = url_adapter.build(  # type: ignore[union-attr]
  File "C:\Users\buule\Desktop\TaskDesk\dfy\venv\lib\site-packages\werkzeug\routing\map.py", line 924, in build
    raise BuildError(endpoint, values, method, self)
werkzeug.routing.exceptions.BuildError: Could not build url for endpoint 'main.index'. Did you mean 'admin.inbox' instead?
[2025-09-28 16:56:22,577] ERROR in app: Exception on /favicon.ico [GET]
Traceback (most recent call last):
  File "C:\Users\buule\Desktop\TaskDesk\dfy\venv\lib\site-packages\flask\app.py", line 917, in full_dispatch_request
    rv = self.dispatch_request()
  File "C:\Users\buule\Desktop\TaskDesk\dfy\venv\lib\site-packages\flask\app.py", line 891, in dispatch_request
    self.raise_routing_exception(req)
  File "C:\Users\buule\Desktop\TaskDesk\dfy\venv\lib\site-packages\flask\app.py", line 500, in raise_routing_exception
    raise request.routing_exception  # type: ignore[misc]
  File "C:\Users\buule\Desktop\TaskDesk\dfy\venv\lib\site-packages\flask\ctx.py", line 362, in match_request
    result = self.url_adapter.match(return_rule=True)  # type: ignore
  File "C:\Users\buule\Desktop\TaskDesk\dfy\venv\lib\site-packages\werkzeug\routing\map.py", line 629, in match
    raise NotFound() from None
werkzeug.exceptions.NotFound: 404 Not Found: The requested URL was not found on the server. If you entered the URL manually please check your spelling and try again.

During handling of the above exception, another exception occurred:

Traceback (most recent call last):
  File "C:\Users\buule\Desktop\TaskDesk\dfy\venv\lib\site-packages\flask\app.py", line 1511, in wsgi_app
    response = self.full_dispatch_request()
  File "C:\Users\buule\Desktop\TaskDesk\dfy\venv\lib\site-packages\flask\app.py", line 919, in full_dispatch_request
    rv = self.handle_user_exception(e)
  File "C:\Users\buule\Desktop\TaskDesk\dfy\venv\lib\site-packages\flask\app.py", line 802, in handle_user_exception
    return self.handle_http_exception(e)
  File "C:\Users\buule\Desktop\TaskDesk\dfy\venv\lib\site-packages\flask\app.py", line 777, in handle_http_exception
    return self.ensure_sync(handler)(e)  # type: ignore[no-any-return]
  File "C:\Users\buule\Desktop\TaskDesk\dfy\app\__init__.py", line 209, in not_found_error
    return render_template("errors/404.html"), 404
  File "C:\Users\buule\Desktop\TaskDesk\dfy\venv\lib\site-packages\flask\templating.py", line 150, in render_template
    return _render(app, template, context)
  File "C:\Users\buule\Desktop\TaskDesk\dfy\venv\lib\site-packages\flask\templating.py", line 131, in _render
    rv = template.render(context)
  File "C:\Users\buule\Desktop\TaskDesk\dfy\venv\lib\site-packages\jinja2\environment.py", line 1295, in render
    self.environment.handle_exception()
  File "C:\Users\buule\Desktop\TaskDesk\dfy\venv\lib\site-packages\jinja2\environment.py", line 942, in handle_exception
    raise rewrite_traceback_stack(source=source)
  File "C:\Users\buule\Desktop\TaskDesk\dfy\app\templates\errors\404.html", line 1, in top-level template code
    {% extends 'base.html' %} {% block content %}
  File "C:\Users\buule\Desktop\TaskDesk\dfy\app\templates\base.html", line 184, in top-level template code
    <a class="navbar-brand d-flex align-items-center" href="{{ url_for('main.index') }}">
  File "C:\Users\buule\Desktop\TaskDesk\dfy\venv\lib\site-packages\flask\app.py", line 1121, in url_for
    return self.handle_url_build_error(error, endpoint, values)
  File "C:\Users\buule\Desktop\TaskDesk\dfy\venv\lib\site-packages\flask\app.py", line 1110, in url_for
    rv = url_adapter.build(  # type: ignore[union-attr]
  File "C:\Users\buule\Desktop\TaskDesk\dfy\venv\lib\site-packages\werkzeug\routing\map.py", line 924, in build
    raise BuildError(endpoint, values, method, self)
werkzeug.routing.exceptions.BuildError: Could not build url for endpoint 'main.index'. Did you mean 'admin.inbox' instead?
[2025-09-28 16:56:39,469] ERROR in app: Exception on / [GET]
Traceback (most recent call last):
  File "C:\Users\buule\Desktop\TaskDesk\dfy\venv\lib\site-packages\flask\app.py", line 1511, in wsgi_app
    response = self.full_dispatch_request()
  File "C:\Users\buule\Desktop\TaskDesk\dfy\venv\lib\site-packages\flask\app.py", line 919, in full_dispatch_request
    rv = self.handle_user_exception(e)
  File "C:\Users\buule\Desktop\TaskDesk\dfy\venv\lib\site-packages\flask\app.py", line 917, in full_dispatch_request
    rv = self.dispatch_request()
  File "C:\Users\buule\Desktop\TaskDesk\dfy\venv\lib\site-packages\flask\app.py", line 902, in dispatch_request
    return self.ensure_sync(self.view_functions[rule.endpoint])(**view_args)  # type: ignore[no-any-return]
  File "C:\Users\buule\Desktop\TaskDesk\dfy\app\__init__.py", line 205, in index
    return render_template("home.html")
  File "C:\Users\buule\Desktop\TaskDesk\dfy\venv\lib\site-packages\flask\templating.py", line 150, in render_template
    return _render(app, template, context)
  File "C:\Users\buule\Desktop\TaskDesk\dfy\venv\lib\site-packages\flask\templating.py", line 131, in _render
    rv = template.render(context)
  File "C:\Users\buule\Desktop\TaskDesk\dfy\venv\lib\site-packages\jinja2\environment.py", line 1295, in render
    self.environment.handle_exception()
  File "C:\Users\buule\Desktop\TaskDesk\dfy\venv\lib\site-packages\jinja2\environment.py", line 942, in handle_exception
    raise rewrite_traceback_stack(source=source)
  File "C:\Users\buule\Desktop\TaskDesk\dfy\app\templates\home.html", line 1, in top-level template code
    {% extends 'base.html' %} {% block content %} {# Home / Landing page for TaskDesk Images expected at /static/img/: hero.jpg, feature-1.jpg, feature-2.jpg, feature-3.jpg, how-1.jpg, how-2.jpg, how-3.jpg, logos/*.svg (company-1.svg ...), testimonial-*.jpg
  File "C:\Users\buule\Desktop\TaskDesk\dfy\app\templates\base.html", line 184, in top-level template code
    <a class="navbar-brand d-flex align-items-center" href="/">
  File "C:\Users\buule\Desktop\TaskDesk\dfy\venv\lib\site-packages\flask\app.py", line 1121, in url_for
    return self.handle_url_build_error(error, endpoint, values)
  File "C:\Users\buule\Desktop\TaskDesk\dfy\venv\lib\site-packages\flask\app.py", line 1110, in url_for
    rv = url_adapter.build(  # type: ignore[union-attr]
  File "C:\Users\buule\Desktop\TaskDesk\dfy\venv\lib\site-packages\werkzeug\routing\map.py", line 924, in build
    raise BuildError(endpoint, values, method, self)
werkzeug.routing.exceptions.BuildError: Could not build url for endpoint 'main.index'. Did you mean 'admin.inbox' instead?
[2025-09-28 16:56:39,543] ERROR in app: Exception on /favicon.ico [GET]
Traceback (most recent call last):
  File "C:\Users\buule\Desktop\TaskDesk\dfy\venv\lib\site-packages\flask\app.py", line 917, in full_dispatch_request
    rv = self.dispatch_request()
  File "C:\Users\buule\Desktop\TaskDesk\dfy\venv\lib\site-packages\flask\app.py", line 891, in dispatch_request
    self.raise_routing_exception(req)
  File "C:\Users\buule\Desktop\TaskDesk\dfy\venv\lib\site-packages\flask\app.py", line 500, in raise_routing_exception
    raise request.routing_exception  # type: ignore[misc]
  File "C:\Users\buule\Desktop\TaskDesk\dfy\venv\lib\site-packages\flask\ctx.py", line 362, in match_request
    result = self.url_adapter.match(return_rule=True)  # type: ignore
  File "C:\Users\buule\Desktop\TaskDesk\dfy\venv\lib\site-packages\werkzeug\routing\map.py", line 629, in match
    raise NotFound() from None
werkzeug.exceptions.NotFound: 404 Not Found: The requested URL was not found on the server. If you entered the URL manually please check your spelling and try again.

During handling of the above exception, another exception occurred:

Traceback (most recent call last):
  File "C:\Users\buule\Desktop\TaskDesk\dfy\venv\lib\site-packages\flask\app.py", line 1511, in wsgi_app
    response = self.full_dispatch_request()
  File "C:\Users\buule\Desktop\TaskDesk\dfy\venv\lib\site-packages\flask\app.py", line 919, in full_dispatch_request
    rv = self.handle_user_exception(e)
  File "C:\Users\buule\Desktop\TaskDesk\dfy\venv\lib\site-packages\flask\app.py", line 802, in handle_user_exception
    return self.handle_http_exception(e)
  File "C:\Users\buule\Desktop\TaskDesk\dfy\venv\lib\site-packages\flask\app.py", line 777, in handle_http_exception
    return self.ensure_sync(handler)(e)  # type: ignore[no-any-return]
  File "C:\Users\buule\Desktop\TaskDesk\dfy\app\__init__.py", line 209, in not_found_error
    return render_template("errors/404.html"), 404
  File "C:\Users\buule\Desktop\TaskDesk\dfy\venv\lib\site-packages\flask\templating.py", line 150, in render_template
    return _render(app, template, context)
  File "C:\Users\buule\Desktop\TaskDesk\dfy\venv\lib\site-packages\flask\templating.py", line 131, in _render
    rv = template.render(context)
  File "C:\Users\buule\Desktop\TaskDesk\dfy\venv\lib\site-packages\jinja2\environment.py", line 1295, in render
    self.environment.handle_exception()
  File "C:\Users\buule\Desktop\TaskDesk\dfy\venv\lib\site-packages\jinja2\environment.py", line 942, in handle_exception
    raise rewrite_traceback_stack(source=source)
  File "C:\Users\buule\Desktop\TaskDesk\dfy\app\templates\errors\404.html", line 1, in top-level template code
    {% extends 'base.html' %} {% block content %}
  File "C:\Users\buule\Desktop\TaskDesk\dfy\app\templates\base.html", line 184, in top-level template code
    <a class="navbar-brand d-flex align-items-center" href="/">
  File "C:\Users\buule\Desktop\TaskDesk\dfy\venv\lib\site-packages\flask\app.py", line 1121, in url_for
    return self.handle_url_build_error(error, endpoint, values)
  File "C:\Users\buule\Desktop\TaskDesk\dfy\venv\lib\site-packages\flask\app.py", line 1110, in url_for
    rv = url_adapter.build(  # type: ignore[union-attr]
  File "C:\Users\buule\Desktop\TaskDesk\dfy\venv\lib\site-packages\werkzeug\routing\map.py", line 924, in build
    raise BuildError(endpoint, values, method, self)
werkzeug.routing.exceptions.BuildError: Could not build url for endpoint 'main.index'. Did you mean 'admin.inbox' instead?
[2025-09-28 16:56:51,729] INFO in __init__: Logging initialized.
[2025-09-28 17:02:56,038] INFO in __init__: Logging initialized.
[2025-09-28 17:04:11,418] INFO in __init__: Logging initialized.
[2025-09-28 17:06:39,232] INFO in __init__: Logging initialized.
[2025-09-28 17:09:14,774] INFO in __init__: Logging initialized.
[2025-09-28 17:10:30,525] INFO in __init__: Logging initialized.
[2025-09-28 17:11:23,207] INFO in __init__: Logging initialized.
[2025-09-28 17:14:10,411] INFO in __init__: Logging initialized.
[2025-09-28 17:15:30,136] INFO in __init__: Logging initialized.
[2025-09-28 17:16:26,169] INFO in __init__: Logging initialized.
[2025-09-28 17:17:01,989] INFO in __init__: Logging initialized.
[2025-09-28 17:21:28,622] INFO in __init__: Logging initialized.
[2025-09-28 17:22:55,678] INFO in __init__: Logging initialized.
[2025-09-28 17:44:25,244] INFO in __init__: Logging initialized.
[2025-09-28 17:51:24,848] INFO in __init__: Logging initialized.
[2025-09-28 17:59:15,878] INFO in __init__: Logging initialized.
[2025-09-28 18:13:43,097] INFO in __init__: Logging initialized.
[2025-09-28 18:19:12,524] INFO in __init__: Logging initialized.
[2025-09-28 18:25:19,706] INFO in __init__: Logging initialized.
[2025-09-28 18:34:08,245] INFO in __init__: Logging initialized.
[2025-09-28 18:34:58,801] INFO in __init__: Logging initialized.
[2025-09-28 18:39:41,308] INFO in __init__: Logging initialized.
[2025-09-28 18:40:58,273] INFO in __init__: Logging initialized.
[2025-09-28 18:49:32,021] INFO in __init__: Logging initialized.
[2025-09-28 18:50:49,140] INFO in __init__: Logging initialized.
[2025-09-28 18:52:01,317] INFO in __init__: Logging initialized.
[2025-09-28 18:54:52,472] INFO in __init__: Logging initialized.
[2025-09-28 19:26:25,754] INFO in __init__: Logging initialized.
[2025-09-28 19:36:07,687] INFO in __init__: Logging initialized.
[2025-09-28 19:37:30,821] INFO in __init__: Logging initialized.
[2025-09-28 20:25:30,246] INFO in email_service: Email sent to ['halifanmwajuma@gmail.com'] | subject=Quote for Task #2 â€” Excel
[2025-09-28 20:28:27,022] INFO in payment_service: Pesapal SubmitOrderRequest status=200
[2025-09-28 20:28:27,023] INFO in payment_service: Pesapal response keys=['order_tracking_id', 'merchant_reference', 'redirect_url', 'error', 'status']
[2025-09-28 20:31:06,065] INFO in __init__: Logging initialized.
